[2025-06-26T02:38:39.770+0000] {processor.py:161} INFO - Started process (PID=56) to work on /opt/airflow/dags/etl.py
[2025-06-26T02:38:39.772+0000] {processor.py:830} INFO - Processing file /opt/airflow/dags/etl.py for tasks to queue
[2025-06-26T02:38:39.775+0000] {logging_mixin.py:188} INFO - [2025-06-26T02:38:39.774+0000] {dagbag.py:545} INFO - Filling up the DagBag from /opt/airflow/dags/etl.py
[2025-06-26T02:38:39.802+0000] {logging_mixin.py:188} INFO - [2025-06-26T02:38:39.793+0000] {dagbag.py:355} ERROR - Failed to import: /opt/airflow/dags/etl.py
Traceback (most recent call last):
  File "/home/airflow/.local/lib/python3.12/site-packages/airflow/models/dagbag.py", line 351, in parse
    loader.exec_module(new_module)
  File "<frozen importlib._bootstrap_external>", line 995, in exec_module
  File "<frozen importlib._bootstrap>", line 488, in _call_with_frames_removed
  File "/opt/airflow/dags/etl.py", line 6, in <module>
    from airflow.utils.dates import days_age
ImportError: cannot import name 'days_age' from 'airflow.utils.dates' (/home/airflow/.local/lib/python3.12/site-packages/airflow/utils/dates.py)
[2025-06-26T02:38:39.807+0000] {processor.py:842} WARNING - No viable dags retrieved from /opt/airflow/dags/etl.py
[2025-06-26T02:38:39.911+0000] {processor.py:183} INFO - Processing /opt/airflow/dags/etl.py took 0.151 seconds
[2025-06-26T02:39:14.385+0000] {processor.py:161} INFO - Started process (PID=122) to work on /opt/airflow/dags/etl.py
[2025-06-26T02:39:14.387+0000] {processor.py:830} INFO - Processing file /opt/airflow/dags/etl.py for tasks to queue
[2025-06-26T02:39:14.391+0000] {logging_mixin.py:188} INFO - [2025-06-26T02:39:14.390+0000] {dagbag.py:545} INFO - Filling up the DagBag from /opt/airflow/dags/etl.py
[2025-06-26T02:39:14.412+0000] {logging_mixin.py:188} INFO - [2025-06-26T02:39:14.405+0000] {dagbag.py:355} ERROR - Failed to import: /opt/airflow/dags/etl.py
Traceback (most recent call last):
  File "/home/airflow/.local/lib/python3.12/site-packages/airflow/models/dagbag.py", line 351, in parse
    loader.exec_module(new_module)
  File "<frozen importlib._bootstrap_external>", line 995, in exec_module
  File "<frozen importlib._bootstrap>", line 488, in _call_with_frames_removed
  File "/opt/airflow/dags/etl.py", line 6, in <module>
    from airflow.utils.dates import days_age
ImportError: cannot import name 'days_age' from 'airflow.utils.dates' (/home/airflow/.local/lib/python3.12/site-packages/airflow/utils/dates.py)
[2025-06-26T02:39:14.417+0000] {processor.py:842} WARNING - No viable dags retrieved from /opt/airflow/dags/etl.py
[2025-06-26T02:39:14.447+0000] {processor.py:183} INFO - Processing /opt/airflow/dags/etl.py took 0.068 seconds
[2025-06-26T02:39:44.776+0000] {processor.py:161} INFO - Started process (PID=173) to work on /opt/airflow/dags/etl.py
[2025-06-26T02:39:44.779+0000] {processor.py:830} INFO - Processing file /opt/airflow/dags/etl.py for tasks to queue
[2025-06-26T02:39:44.787+0000] {logging_mixin.py:188} INFO - [2025-06-26T02:39:44.786+0000] {dagbag.py:545} INFO - Filling up the DagBag from /opt/airflow/dags/etl.py
[2025-06-26T02:39:44.811+0000] {logging_mixin.py:188} INFO - [2025-06-26T02:39:44.804+0000] {dagbag.py:355} ERROR - Failed to import: /opt/airflow/dags/etl.py
Traceback (most recent call last):
  File "/home/airflow/.local/lib/python3.12/site-packages/airflow/models/dagbag.py", line 351, in parse
    loader.exec_module(new_module)
  File "<frozen importlib._bootstrap_external>", line 995, in exec_module
  File "<frozen importlib._bootstrap>", line 488, in _call_with_frames_removed
  File "/opt/airflow/dags/etl.py", line 6, in <module>
    from airflow.utils.dates import days_age
ImportError: cannot import name 'days_age' from 'airflow.utils.dates' (/home/airflow/.local/lib/python3.12/site-packages/airflow/utils/dates.py)
[2025-06-26T02:39:44.814+0000] {processor.py:842} WARNING - No viable dags retrieved from /opt/airflow/dags/etl.py
[2025-06-26T02:39:44.878+0000] {processor.py:183} INFO - Processing /opt/airflow/dags/etl.py took 0.134 seconds
[2025-06-26T02:40:15.098+0000] {processor.py:161} INFO - Started process (PID=233) to work on /opt/airflow/dags/etl.py
[2025-06-26T02:40:15.099+0000] {processor.py:830} INFO - Processing file /opt/airflow/dags/etl.py for tasks to queue
[2025-06-26T02:40:15.101+0000] {logging_mixin.py:188} INFO - [2025-06-26T02:40:15.101+0000] {dagbag.py:545} INFO - Filling up the DagBag from /opt/airflow/dags/etl.py
[2025-06-26T02:40:15.114+0000] {logging_mixin.py:188} INFO - [2025-06-26T02:40:15.110+0000] {dagbag.py:355} ERROR - Failed to import: /opt/airflow/dags/etl.py
Traceback (most recent call last):
  File "/home/airflow/.local/lib/python3.12/site-packages/airflow/models/dagbag.py", line 351, in parse
    loader.exec_module(new_module)
  File "<frozen importlib._bootstrap_external>", line 995, in exec_module
  File "<frozen importlib._bootstrap>", line 488, in _call_with_frames_removed
  File "/opt/airflow/dags/etl.py", line 6, in <module>
    from airflow.utils.dates import days_age
ImportError: cannot import name 'days_age' from 'airflow.utils.dates' (/home/airflow/.local/lib/python3.12/site-packages/airflow/utils/dates.py)
[2025-06-26T02:40:15.116+0000] {processor.py:842} WARNING - No viable dags retrieved from /opt/airflow/dags/etl.py
[2025-06-26T02:40:15.137+0000] {processor.py:183} INFO - Processing /opt/airflow/dags/etl.py took 0.044 seconds
[2025-06-26T02:40:45.301+0000] {processor.py:161} INFO - Started process (PID=293) to work on /opt/airflow/dags/etl.py
[2025-06-26T02:40:45.302+0000] {processor.py:830} INFO - Processing file /opt/airflow/dags/etl.py for tasks to queue
[2025-06-26T02:40:45.305+0000] {logging_mixin.py:188} INFO - [2025-06-26T02:40:45.304+0000] {dagbag.py:545} INFO - Filling up the DagBag from /opt/airflow/dags/etl.py
[2025-06-26T02:40:45.321+0000] {logging_mixin.py:188} INFO - [2025-06-26T02:40:45.316+0000] {dagbag.py:355} ERROR - Failed to import: /opt/airflow/dags/etl.py
Traceback (most recent call last):
  File "/home/airflow/.local/lib/python3.12/site-packages/airflow/models/dagbag.py", line 351, in parse
    loader.exec_module(new_module)
  File "<frozen importlib._bootstrap_external>", line 995, in exec_module
  File "<frozen importlib._bootstrap>", line 488, in _call_with_frames_removed
  File "/opt/airflow/dags/etl.py", line 6, in <module>
    from airflow.utils.dates import days_age
ImportError: cannot import name 'days_age' from 'airflow.utils.dates' (/home/airflow/.local/lib/python3.12/site-packages/airflow/utils/dates.py)
[2025-06-26T02:40:45.324+0000] {processor.py:842} WARNING - No viable dags retrieved from /opt/airflow/dags/etl.py
[2025-06-26T02:40:45.350+0000] {processor.py:183} INFO - Processing /opt/airflow/dags/etl.py took 0.054 seconds
[2025-06-26T02:40:56.626+0000] {processor.py:161} INFO - Started process (PID=317) to work on /opt/airflow/dags/etl.py
[2025-06-26T02:40:56.642+0000] {processor.py:830} INFO - Processing file /opt/airflow/dags/etl.py for tasks to queue
[2025-06-26T02:40:56.645+0000] {logging_mixin.py:188} INFO - [2025-06-26T02:40:56.644+0000] {dagbag.py:545} INFO - Filling up the DagBag from /opt/airflow/dags/etl.py
[2025-06-26T02:40:56.665+0000] {logging_mixin.py:188} WARNING - /opt/airflow/dags/etl.py:10 SyntaxWarning: invalid escape sequence '\.'
[2025-06-26T02:40:56.703+0000] {logging_mixin.py:188} INFO - [2025-06-26T02:40:56.694+0000] {dagbag.py:355} ERROR - Failed to import: /opt/airflow/dags/etl.py
Traceback (most recent call last):
  File "/home/airflow/.local/lib/python3.12/site-packages/airflow/models/dagbag.py", line 351, in parse
    loader.exec_module(new_module)
  File "<frozen importlib._bootstrap_external>", line 995, in exec_module
  File "<frozen importlib._bootstrap>", line 488, in _call_with_frames_removed
  File "/opt/airflow/dags/etl.py", line 21, in <module>
    "start_date" : days_age(1)
                   ^^^^^^^^
NameError: name 'days_age' is not defined
[2025-06-26T02:40:56.708+0000] {processor.py:842} WARNING - No viable dags retrieved from /opt/airflow/dags/etl.py
[2025-06-26T02:40:56.801+0000] {processor.py:183} INFO - Processing /opt/airflow/dags/etl.py took 0.180 seconds
[2025-06-26T02:41:03.954+0000] {processor.py:161} INFO - Started process (PID=320) to work on /opt/airflow/dags/etl.py
[2025-06-26T02:41:03.955+0000] {processor.py:830} INFO - Processing file /opt/airflow/dags/etl.py for tasks to queue
[2025-06-26T02:41:03.957+0000] {logging_mixin.py:188} INFO - [2025-06-26T02:41:03.957+0000] {dagbag.py:545} INFO - Filling up the DagBag from /opt/airflow/dags/etl.py
[2025-06-26T02:41:03.969+0000] {logging_mixin.py:188} WARNING - /opt/airflow/dags/etl.py:10 SyntaxWarning: invalid escape sequence '\.'
[2025-06-26T02:41:03.987+0000] {logging_mixin.py:188} INFO - [2025-06-26T02:41:03.982+0000] {dagbag.py:355} ERROR - Failed to import: /opt/airflow/dags/etl.py
Traceback (most recent call last):
  File "/home/airflow/.local/lib/python3.12/site-packages/airflow/models/dagbag.py", line 351, in parse
    loader.exec_module(new_module)
  File "<frozen importlib._bootstrap_external>", line 995, in exec_module
  File "<frozen importlib._bootstrap>", line 488, in _call_with_frames_removed
  File "/opt/airflow/dags/etl.py", line 21, in <module>
    "start_date" : datetime(2025, 1, 1)
                   ^^^^^^^^
NameError: name 'datetime' is not defined. Did you forget to import 'datetime'
[2025-06-26T02:41:03.990+0000] {processor.py:842} WARNING - No viable dags retrieved from /opt/airflow/dags/etl.py
[2025-06-26T02:41:04.014+0000] {processor.py:183} INFO - Processing /opt/airflow/dags/etl.py took 0.064 seconds
[2025-06-26T02:41:09.114+0000] {processor.py:161} INFO - Started process (PID=326) to work on /opt/airflow/dags/etl.py
[2025-06-26T02:41:09.115+0000] {processor.py:830} INFO - Processing file /opt/airflow/dags/etl.py for tasks to queue
[2025-06-26T02:41:09.117+0000] {logging_mixin.py:188} INFO - [2025-06-26T02:41:09.116+0000] {dagbag.py:545} INFO - Filling up the DagBag from /opt/airflow/dags/etl.py
[2025-06-26T02:41:09.131+0000] {logging_mixin.py:188} WARNING - /opt/airflow/dags/etl.py:11 SyntaxWarning: invalid escape sequence '\.'
[2025-06-26T02:41:09.145+0000] {logging_mixin.py:188} INFO - [2025-06-26T02:41:09.142+0000] {dagbag.py:355} ERROR - Failed to import: /opt/airflow/dags/etl.py
Traceback (most recent call last):
  File "/home/airflow/.local/lib/python3.12/site-packages/airflow/models/dagbag.py", line 351, in parse
    loader.exec_module(new_module)
  File "<frozen importlib._bootstrap_external>", line 995, in exec_module
  File "<frozen importlib._bootstrap>", line 488, in _call_with_frames_removed
  File "/opt/airflow/dags/etl.py", line 22, in <module>
    "start_date" : datetime(2025, 1, 1)
                   ^^^^^^^^^^^^^^^^^^^^
TypeError: 'module' object is not callable. Did you mean: 'datetime.datetime(...)'?
[2025-06-26T02:41:09.148+0000] {processor.py:842} WARNING - No viable dags retrieved from /opt/airflow/dags/etl.py
[2025-06-26T02:41:09.168+0000] {processor.py:183} INFO - Processing /opt/airflow/dags/etl.py took 0.060 seconds
[2025-06-26T02:41:24.478+0000] {processor.py:161} INFO - Started process (PID=379) to work on /opt/airflow/dags/etl.py
[2025-06-26T02:41:24.479+0000] {processor.py:830} INFO - Processing file /opt/airflow/dags/etl.py for tasks to queue
[2025-06-26T02:41:24.481+0000] {logging_mixin.py:188} INFO - [2025-06-26T02:41:24.481+0000] {dagbag.py:545} INFO - Filling up the DagBag from /opt/airflow/dags/etl.py
[2025-06-26T02:41:24.496+0000] {logging_mixin.py:188} WARNING - /opt/airflow/dags/etl.py:10 SyntaxWarning: invalid escape sequence '\.'
[2025-06-26T02:41:24.513+0000] {logging_mixin.py:188} INFO - [2025-06-26T02:41:24.508+0000] {dagbag.py:355} ERROR - Failed to import: /opt/airflow/dags/etl.py
Traceback (most recent call last):
  File "/home/airflow/.local/lib/python3.12/site-packages/airflow/models/dagbag.py", line 351, in parse
    loader.exec_module(new_module)
  File "<frozen importlib._bootstrap_external>", line 995, in exec_module
  File "<frozen importlib._bootstrap>", line 488, in _call_with_frames_removed
  File "/opt/airflow/dags/etl.py", line 21, in <module>
    "start_date" : datetime(2025, 1, 1)
                   ^^^^^^^^
NameError: name 'datetime' is not defined. Did you forget to import 'datetime'
[2025-06-26T02:41:24.516+0000] {processor.py:842} WARNING - No viable dags retrieved from /opt/airflow/dags/etl.py
[2025-06-26T02:41:24.538+0000] {processor.py:183} INFO - Processing /opt/airflow/dags/etl.py took 0.066 seconds
[2025-06-26T02:41:29.525+0000] {processor.py:161} INFO - Started process (PID=380) to work on /opt/airflow/dags/etl.py
[2025-06-26T02:41:29.526+0000] {processor.py:830} INFO - Processing file /opt/airflow/dags/etl.py for tasks to queue
[2025-06-26T02:41:29.528+0000] {logging_mixin.py:188} INFO - [2025-06-26T02:41:29.527+0000] {dagbag.py:545} INFO - Filling up the DagBag from /opt/airflow/dags/etl.py
[2025-06-26T02:41:29.546+0000] {logging_mixin.py:188} WARNING - /opt/airflow/dags/etl.py:10 SyntaxWarning: invalid escape sequence '\.'
[2025-06-26T02:41:29.564+0000] {processor.py:840} INFO - DAG(s) 'weather_etl' retrieved from /opt/airflow/dags/etl.py
[2025-06-26T02:41:29.673+0000] {logging_mixin.py:188} INFO - [2025-06-26T02:41:29.672+0000] {override.py:1829} INFO - Created Permission View: can edit on DAG:weather_etl
[2025-06-26T02:41:29.684+0000] {logging_mixin.py:188} INFO - [2025-06-26T02:41:29.684+0000] {override.py:1829} INFO - Created Permission View: can read on DAG:weather_etl
[2025-06-26T02:41:29.693+0000] {logging_mixin.py:188} INFO - [2025-06-26T02:41:29.693+0000] {override.py:1829} INFO - Created Permission View: can delete on DAG:weather_etl
[2025-06-26T02:41:29.693+0000] {logging_mixin.py:188} INFO - [2025-06-26T02:41:29.693+0000] {dag.py:3096} INFO - Sync 1 DAGs
[2025-06-26T02:41:29.706+0000] {logging_mixin.py:188} INFO - [2025-06-26T02:41:29.705+0000] {dag.py:3118} INFO - Creating ORM DAG for weather_etl
[2025-06-26T02:41:29.716+0000] {logging_mixin.py:188} INFO - [2025-06-26T02:41:29.715+0000] {dag.py:3954} INFO - Setting next_dagrun for weather_etl to 2025-06-25 00:00:00+00:00, run_after=2025-06-26 00:00:00+00:00
[2025-06-26T02:41:29.738+0000] {processor.py:183} INFO - Processing /opt/airflow/dags/etl.py took 0.220 seconds
[2025-06-26T02:41:31.687+0000] {processor.py:161} INFO - Started process (PID=382) to work on /opt/airflow/dags/etl.py
[2025-06-26T02:41:31.688+0000] {processor.py:830} INFO - Processing file /opt/airflow/dags/etl.py for tasks to queue
[2025-06-26T02:41:31.690+0000] {logging_mixin.py:188} INFO - [2025-06-26T02:41:31.690+0000] {dagbag.py:545} INFO - Filling up the DagBag from /opt/airflow/dags/etl.py
[2025-06-26T02:41:31.704+0000] {logging_mixin.py:188} WARNING - /opt/airflow/dags/etl.py:11 SyntaxWarning: invalid escape sequence '\.'
[2025-06-26T02:41:31.722+0000] {processor.py:840} INFO - DAG(s) 'weather_etl' retrieved from /opt/airflow/dags/etl.py
[2025-06-26T02:41:31.736+0000] {logging_mixin.py:188} INFO - [2025-06-26T02:41:31.736+0000] {dag.py:3096} INFO - Sync 1 DAGs
[2025-06-26T02:41:31.759+0000] {logging_mixin.py:188} INFO - [2025-06-26T02:41:31.758+0000] {dag.py:3954} INFO - Setting next_dagrun for weather_etl to 2025-06-25 00:00:00+00:00, run_after=2025-06-26 00:00:00+00:00
[2025-06-26T02:41:31.782+0000] {processor.py:183} INFO - Processing /opt/airflow/dags/etl.py took 0.101 seconds
[2025-06-26T02:42:01.880+0000] {processor.py:161} INFO - Started process (PID=442) to work on /opt/airflow/dags/etl.py
[2025-06-26T02:42:01.881+0000] {processor.py:830} INFO - Processing file /opt/airflow/dags/etl.py for tasks to queue
[2025-06-26T02:42:01.882+0000] {logging_mixin.py:188} INFO - [2025-06-26T02:42:01.882+0000] {dagbag.py:545} INFO - Filling up the DagBag from /opt/airflow/dags/etl.py
[2025-06-26T02:42:01.905+0000] {processor.py:840} INFO - DAG(s) 'weather_etl' retrieved from /opt/airflow/dags/etl.py
[2025-06-26T02:42:01.925+0000] {logging_mixin.py:188} INFO - [2025-06-26T02:42:01.925+0000] {dag.py:3096} INFO - Sync 1 DAGs
[2025-06-26T02:42:01.947+0000] {logging_mixin.py:188} INFO - [2025-06-26T02:42:01.947+0000] {dag.py:3954} INFO - Setting next_dagrun for weather_etl to 2025-06-25 00:00:00+00:00, run_after=2025-06-26 00:00:00+00:00
[2025-06-26T02:42:01.969+0000] {processor.py:183} INFO - Processing /opt/airflow/dags/etl.py took 0.096 seconds
